<?xml version="1.0" ?>
<!-- =================================================================================== -->
<!-- |    This document was autogenerated by xacro from ./qbshin.urdf.xacro            | -->
<!-- |    EDITING THIS FILE BY HAND IS NOT RECOMMENDED                                 | -->
<!-- =================================================================================== -->
<robot name="qbshin">
  <material name="qbshin/optional">
    <color rgba="0.0 0.5 0.8 1.0"/>
  </material>
  <material name="qbshin/base">
    <color rgba="0.35 0.35 0.35 1.0"/>
  </material>
  <material name="qbshin/palm">
    <color rgba="0.35 0.35 0.35 1.0"/>
  </material>
  <material name="qbshin/knuckle">
    <color rgba="0.35 0.35 0.35 1.0"/>
  </material>
  <material name="qbshin/proximal">
    <color rgba="0.35 0.35 0.35 1.0"/>
  </material>
  <material name="qbshin/middle">
    <color rgba="0.35 0.35 0.35 1.0"/>
  </material>
  <material name="qbshin/distal">
    <color rgba="0.35 0.35 0.35 1.0"/>
  </material>
  <material name="qbshin/default">
    <color rgba="0.35 0.35 0.35 1.0"/>
  </material>
  <link name="root_link"/>
  <joint name="qbshin_base_fixed_joint" type="fixed">
    <origin rpy="0 0 0" xyz="0 0 0"/>
    <parent link="root_link"/>
    <child link="qbshin_base_link"/>
  </joint>
  <link name="qbshin_base_link">
    <inertial>
      <mass value="0.45"/>
      <origin rpy="0 0 0" xyz="0.0030 -0.0449 0.0135"/>
      <inertia ixx="0.00045" ixy="0.0" ixz="0.0" iyy="0.0006" iyz="0.0" izz="0.00025"/>
    </inertial>
    <visual>
      <origin rpy="0 0 0" xyz="0 0 0"/>
      <geometry>
        <mesh filename="package://meshes/shin_wrist_urdf.stl" scale="0.001 0.001 0.001"/>
      </geometry>
      <material name="qbshin/base"/>
    </visual>
    <collision>
      <origin rpy="0 0 0" xyz="0 0 0"/>
      <geometry>
        <mesh filename="package://meshes/shin_wrist_urdf.stl" scale="0.001 0.001 0.001"/>
      </geometry>
    </collision>
  </link>
  <gazebo reference="qbshin_base_link">
    <self_collide>1</self_collide>
    <!-- TODO: add other Gazebo Link properties (http://sdformat.org/spec?elem=link) -->
    <!--      <collision>-->
    <!--        <surface>-->
    <!--          <contact>-->
    <!--            <ode>-->
    <!--              <kp>1.0</kp>-->
    <!--              <kd>0.01</kd>-->
    <!--              <max_vel>0.0</max_vel>-->
    <!--              <min_depth>0.001</min_depth>-->
    <!--            </ode>-->
    <!--          </contact>-->
    <!--          <friction>-->
    <!--            <ode>-->
    <!--              <mu>0.9</mu>-->
    <!--              <mu2>0.9</mu2>-->
    <!--            </ode>-->
    <!--          </friction>-->
    <!--        </surface>-->
    <!--      </collision>-->
  </gazebo>
  <joint name="qbshin_palm_fixed_joint" type="fixed">
    <origin rpy="1.57 0 0" xyz="-0.005 0.0 0.071"/>
    <parent link="qbshin_base_link"/>
    <child link="qbshin_palm_link"/>
  </joint>
  <link name="qbshin_palm_link">
    <inertial>
      <mass value="0.45"/>
      <origin rpy="0 0 0" xyz="0.0030 -0.0449 -0.0135"/>
      <inertia ixx="0.00045" ixy="0.0" ixz="0.0" iyy="0.0006" iyz="0.0" izz="0.00025"/>
    </inertial>
    <visual>
      <origin rpy="0 0 0" xyz="0 0 0"/>
      <geometry>
        <mesh filename="package://meshes/shin_frame_urdf.stl" scale="0.001 0.001 0.001"/>
      </geometry>
      <material name="qbshin/palm"/>
    </visual>
    <collision>
      <origin rpy="0 0 0" xyz="0 0 0"/>
      <geometry>
        <mesh filename="package://meshes/shin_frame_urdf.stl" scale="0.001 0.001 0.001"/>
      </geometry>
    </collision>
  </link>
  <gazebo reference="qbshin_palm_link">
    <self_collide>1</self_collide>
    <!-- TODO: add other Gazebo Link properties (http://sdformat.org/spec?elem=link) -->
    <!--      <collision>-->
    <!--        <surface>-->
    <!--          <contact>-->
    <!--            <ode>-->
    <!--              <kp>1.0</kp>-->
    <!--              <kd>0.01</kd>-->
    <!--              <max_vel>0.0</max_vel>-->
    <!--              <min_depth>0.001</min_depth>-->
    <!--            </ode>-->
    <!--          </contact>-->
    <!--          <friction>-->
    <!--            <ode>-->
    <!--              <mu>0.9</mu>-->
    <!--              <mu2>0.9</mu2>-->
    <!--            </ode>-->
    <!--          </friction>-->
    <!--        </surface>-->
    <!--      </collision>-->
  </gazebo>
  <joint name="qbshin_synergy_joint" type="revolute">
    <origin rpy="0 0 0" xyz="0 0 0"/>
    <parent link="qbshin_palm_link"/>
    <child link="qbshin_synergy_tendon_virtual_link"/>
    <axis xyz="0 0 1"/>
    <dynamics damping="0.0" friction="0.0"/>
    <limit effort="100" lower="0.0" upper="1.0" velocity="100"/>
  </joint>
  <transmission name="qbshin_synergy_transmission">
    <type>transmission_interface/qbMoveTransmission</type>
    <joint name="qbshin_synergy_joint">
      <hardwareInterface>hardware_interface/EffortJointInterface</hardwareInterface>
    </joint>
    <actuator name="qbshin_synergy_joint">
      <hardwareInterface>hardware_interface/EffortJointInterface</hardwareInterface>
    </actuator>
  </transmission>
  <link name="qbshin_synergy_tendon_virtual_link">
    <inertial>
      <origin rpy="0 0 0" xyz="0 0 0"/>
      <mass value="1e-4"/>
      <inertia ixx="1e-9" ixy="0.0" ixz="0.0" iyy="1e-9" iyz="0.0" izz="1e-9"/>
    </inertial>
  </link>
  <joint name="qbshin_thumb_knuckle_joint" type="revolute">
    <origin rpy="-1.57 3.5 -0.68" xyz="-0.044 0.027 -0.03"/>
    <parent link="qbshin_palm_link"/>
    <child link="qbshin_thumb_knuckle_link"/>
    <axis xyz="0 0 -1"/>
    <dynamics damping="0.0" friction="0.0"/>
    <limit effort="100" lower="0.0" upper="1.571" velocity="100"/>
    <mimic joint="qbshin_synergy_joint" multiplier="2.542"/>
  </joint>
  <transmission name="qbshin_transmission">
    <type>transmission_interface/qbMoveTransmission</type>
    <joint name="qbshin_thumb_knuckle_joint">
      <hardwareInterface>hardware_interface/EffortJointInterface</hardwareInterface>
    </joint>
    <actuator name="qbshin_thumb_knuckle_joint">
      <hardwareInterface>hardware_interface/EffortJointInterface</hardwareInterface>
    </actuator>
  </transmission>
  <gazebo reference="qbshin_thumb_knuckle_joint">
    <!-- TODO: add other Gazebo Joint properties (http://sdformat.org/spec?elem=joint) -->
  </gazebo>
  <link name="qbshin_thumb_knuckle_link">
    <inertial>
      <mass value="0.01"/>
      <origin rpy="0 0 0" xyz="1.3071561e-02 -2.7357764e-03 6.4347823e-04"/>
      <inertia ixx="3.5865978e-07" ixy="2.0944224e-07" ixz="-6.8657569e-08" iyy="1.3885564e-06" iyz="3.2170608e-08" izz="1.3571203e-06"/>
    </inertial>
    <visual>
      <origin rpy="0 0 0" xyz="0 0 0"/>
      <geometry>
        <mesh filename="package://meshes/sh_ph_thumb_inj_d9_r_urdf.stl" scale="0.001 0.001 0.001"/>
      </geometry>
      <material name="qbshin/knuckle"/>
    </visual>
    <collision>
      <origin rpy="0 0 0" xyz="0 0 0"/>
      <geometry>
        <mesh filename="package://meshes/sh_ph_thumb_inj_d9_r_urdf.stl" scale="0.001 0.001 0.001"/>
      </geometry>
    </collision>
  </link>
  <gazebo reference="qbshin_thumb_knuckle_link">
    <self_collide>1</self_collide>
    <!-- TODO: add other Gazebo Link properties (http://sdformat.org/spec?elem=link) -->
    <!--      <collision>-->
    <!--        <surface>-->
    <!--          <contact>-->
    <!--            <ode>-->
    <!--              <kp>1.0</kp>-->
    <!--              <kd>0.01</kd>-->
    <!--              <max_vel>0.0</max_vel>-->
    <!--              <min_depth>0.001</min_depth>-->
    <!--            </ode>-->
    <!--          </contact>-->
    <!--          <friction>-->
    <!--            <ode>-->
    <!--              <mu>0.9</mu>-->
    <!--              <mu2>0.9</mu2>-->
    <!--            </ode>-->
    <!--          </friction>-->
    <!--        </surface>-->
    <!--      </collision>-->
  </gazebo>
  <joint name="qbshin_thumb_proximal_joint" type="revolute">
    <origin rpy="-1.57 0.0 0.0" xyz="0.02 -0.003 0"/>
    <parent link="qbshin_thumb_knuckle_link"/>
    <child link="qbshin_thumb_proximal_virtual_link"/>
    <axis xyz="0 0 -1"/>
    <dynamics damping="0.0" friction="0.0"/>
    <limit effort="100" lower="0.0" upper="0.785" velocity="100"/>
    <mimic joint="qbshin_synergy_joint" multiplier="0.785"/>
  </joint>
  <transmission name="qbshin_transmission">
    <type>transmission_interface/qbMoveTransmission</type>
    <joint name="qbshin_thumb_proximal_joint">
      <hardwareInterface>hardware_interface/EffortJointInterface</hardwareInterface>
    </joint>
    <actuator name="qbshin_thumb_proximal_joint">
      <hardwareInterface>hardware_interface/EffortJointInterface</hardwareInterface>
    </actuator>
  </transmission>
  <gazebo reference="qbshin_thumb_proximal_joint">
    <!-- TODO: add other Gazebo Joint properties (http://sdformat.org/spec?elem=joint) -->
  </gazebo>
  <link name="qbshin_thumb_proximal_virtual_link">
    <inertial>
      <origin rpy="0 0 0" xyz="0 0 0"/>
      <mass value="1e-4"/>
      <inertia ixx="1e-9" ixy="0.0" ixz="0.0" iyy="1e-9" iyz="0.0" izz="1e-9"/>
    </inertial>
  </link>
  <joint name="qbshin_thumb_proximal_virtual_joint" type="revolute">
    <origin rpy="0 0 0" xyz="0.013 0 0"/>
    <parent link="qbshin_thumb_proximal_virtual_link"/>
    <child link="qbshin_thumb_proximal_link"/>
    <axis xyz="0 0 -1"/>
    <dynamics damping="0.0" friction="0.0"/>
    <limit effort="100" lower="0.0" upper="0.785" velocity="100"/>
    <mimic joint="qbshin_thumb_proximal_joint" multiplier="1.0"/>
  </joint>
  <transmission name="qbshin_transmission">
    <type>transmission_interface/qbMoveTransmission</type>
    <joint name="qbshin_thumb_proximal_virtual_joint">
      <hardwareInterface>hardware_interface/EffortJointInterface</hardwareInterface>
    </joint>
    <actuator name="qbshin_thumb_proximal_virtual_joint">
      <hardwareInterface>hardware_interface/EffortJointInterface</hardwareInterface>
    </actuator>
  </transmission>
  <gazebo reference="qbshin_thumb_proximal_virtual_joint">
    <!-- TODO: add other Gazebo Joint properties (http://sdformat.org/spec?elem=joint) -->
  </gazebo>
  <link name="qbshin_thumb_proximal_link">
    <inertial>
      <mass value="0.0082"/>
      <origin rpy="0 0 0" xyz="8.7707437e-03 -1.7863138e-03 0.0"/>
      <inertia ixx="2.2722068e-07" ixy="1.1586053e-08" ixz="0.0" iyy="5.5947233e-07" iyz="0.0" izz="5.9562195e-07"/>
    </inertial>
    <visual>
      <origin rpy="0 0 0" xyz="0 0 0"/>
      <geometry>
        <mesh filename="package://meshes/mc_h_pad_30_urdf.stl" scale="0.001 0.001 0.001"/>
      </geometry>
      <material name="qbshin/proximal"/>
    </visual>
    <collision>
      <origin rpy="0 0 0" xyz="0 0 0"/>
      <geometry>
        <mesh filename="package://meshes/mc_h_pad_30_urdf.stl" scale="0.001 0.001 0.001"/>
      </geometry>
    </collision>
  </link>
  <gazebo reference="qbshin_thumb_proximal_link">
    <self_collide>1</self_collide>
    <!-- TODO: add other Gazebo Link properties (http://sdformat.org/spec?elem=link) -->
    <!--      <collision>-->
    <!--        <surface>-->
    <!--          <contact>-->
    <!--            <ode>-->
    <!--              <kp>1.0</kp>-->
    <!--              <kd>0.01</kd>-->
    <!--              <max_vel>0.0</max_vel>-->
    <!--              <min_depth>0.001</min_depth>-->
    <!--            </ode>-->
    <!--          </contact>-->
    <!--          <friction>-->
    <!--            <ode>-->
    <!--              <mu>0.9</mu>-->
    <!--              <mu2>0.9</mu2>-->
    <!--            </ode>-->
    <!--          </friction>-->
    <!--        </surface>-->
    <!--      </collision>-->
  </gazebo>
  <joint name="qbshin_thumb_distal_joint" type="revolute">
    <origin rpy="0.0 0.0 0.0" xyz="0.014 0.002 0"/>
    <parent link="qbshin_thumb_proximal_link"/>
    <child link="qbshin_thumb_distal_virtual_link"/>
    <axis xyz="0 0 -1"/>
    <dynamics damping="0.0" friction="0.0"/>
    <limit effort="100" lower="0.0" upper="0.785" velocity="100"/>
    <mimic joint="qbshin_synergy_joint" multiplier="0.785"/>
  </joint>
  <transmission name="qbshin_transmission">
    <type>transmission_interface/qbMoveTransmission</type>
    <joint name="qbshin_thumb_distal_joint">
      <hardwareInterface>hardware_interface/EffortJointInterface</hardwareInterface>
    </joint>
    <actuator name="qbshin_thumb_distal_joint">
      <hardwareInterface>hardware_interface/EffortJointInterface</hardwareInterface>
    </actuator>
  </transmission>
  <gazebo reference="qbshin_thumb_distal_joint">
    <!-- TODO: add other Gazebo Joint properties (http://sdformat.org/spec?elem=joint) -->
  </gazebo>
  <link name="qbshin_thumb_distal_virtual_link">
    <inertial>
      <origin rpy="0 0 0" xyz="0 0 0"/>
      <mass value="1e-4"/>
      <inertia ixx="1e-9" ixy="0.0" ixz="0.0" iyy="1e-9" iyz="0.0" izz="1e-9"/>
    </inertial>
  </link>
  <joint name="qbshin_thumb_distal_virtual_joint" type="revolute">
    <origin rpy="0 0 0" xyz="0.013 0 0"/>
    <parent link="qbshin_thumb_distal_virtual_link"/>
    <child link="qbshin_thumb_distal_link"/>
    <axis xyz="0 0 -1"/>
    <dynamics damping="0.0" friction="0.0"/>
    <limit effort="100" lower="0.0" upper="0.785" velocity="100"/>
    <mimic joint="qbshin_thumb_distal_joint" multiplier="1.0"/>
  </joint>
  <transmission name="qbshin_transmission">
    <type>transmission_interface/qbMoveTransmission</type>
    <joint name="qbshin_thumb_distal_virtual_joint">
      <hardwareInterface>hardware_interface/EffortJointInterface</hardwareInterface>
    </joint>
    <actuator name="qbshin_thumb_distal_virtual_joint">
      <hardwareInterface>hardware_interface/EffortJointInterface</hardwareInterface>
    </actuator>
  </transmission>
  <gazebo reference="qbshin_thumb_distal_virtual_joint">
    <!-- TODO: add other Gazebo Joint properties (http://sdformat.org/spec?elem=joint) -->
  </gazebo>
  <link name="qbshin_thumb_distal_link">
    <inertial>
      <mass value="0.009"/>
      <origin rpy="0 0 0" xyz="8.8025467e-03 -1.7219289e-03 0.0"/>
      <inertia ixx="2.6586142e-07" ixy="1.2416847e-08" ixz="0.0" iyy="5.9935767e-07" iyz="0.0" izz="6.6781963e-07"/>
    </inertial>
    <visual>
      <origin rpy="0 0 0" xyz="0 0 0"/>
      <geometry>
        <mesh filename="package://meshes/mc_h_pad_dist_urdf.stl" scale="0.001 0.001 0.001"/>
      </geometry>
      <material name="qbshin/distal"/>
    </visual>
    <collision>
      <origin rpy="0 0 0" xyz="0 0 0"/>
      <geometry>
        <mesh filename="package://meshes/mc_h_pad_dist_urdf.stl" scale="0.001 0.001 0.001"/>
      </geometry>
    </collision>
  </link>
  <gazebo reference="qbshin_thumb_distal_link">
    <self_collide>1</self_collide>
    <!-- TODO: add other Gazebo Link properties (http://sdformat.org/spec?elem=link) -->
    <!--      <collision>-->
    <!--        <surface>-->
    <!--          <contact>-->
    <!--            <ode>-->
    <!--              <kp>1.0</kp>-->
    <!--              <kd>0.01</kd>-->
    <!--              <max_vel>0.0</max_vel>-->
    <!--              <min_depth>0.001</min_depth>-->
    <!--            </ode>-->
    <!--          </contact>-->
    <!--          <friction>-->
    <!--            <ode>-->
    <!--              <mu>0.9</mu>-->
    <!--              <mu2>0.9</mu2>-->
    <!--            </ode>-->
    <!--          </friction>-->
    <!--        </surface>-->
    <!--      </collision>-->
  </gazebo>
  <joint name="qbshin_index_knuckle_joint" type="revolute">
    <origin rpy="1.57 0 1.57" xyz="-0.032 0.062 -0.022"/>
    <parent link="qbshin_palm_link"/>
    <child link="qbshin_index_knuckle_link"/>
    <axis xyz="0 0 -1"/>
    <dynamics damping="0.0" friction="0.0"/>
    <limit effort="100" lower="-0.524" upper="0.524" velocity="100"/>
    <mimic joint="qbshin_synergy_joint" multiplier="-0.2"/>
  </joint>
  <transmission name="qbshin_transmission">
    <type>transmission_interface/qbMoveTransmission</type>
    <joint name="qbshin_index_knuckle_joint">
      <hardwareInterface>hardware_interface/EffortJointInterface</hardwareInterface>
    </joint>
    <actuator name="qbshin_index_knuckle_joint">
      <hardwareInterface>hardware_interface/EffortJointInterface</hardwareInterface>
    </actuator>
  </transmission>
  <gazebo reference="qbshin_index_knuckle_joint">
    <!-- TODO: add other Gazebo Joint properties (http://sdformat.org/spec?elem=joint) -->
  </gazebo>
  <link name="qbshin_index_knuckle_link">
    <inertial>
      <mass value="0.0095"/>
      <origin rpy="0 0 0" xyz="4.2753603e-04  0.0 -1.4321738e-03"/>
      <inertia ixx="6.4337303e-07" ixy="0.0" ixz="-3.9373913e-08" iyy="1.1253771e-06" iyz="0.0" izz="7.2336948e-07"/>
    </inertial>
    <visual>
      <origin rpy="0 0 0" xyz="0 0 0"/>
      <geometry>
        <mesh filename="package://meshes/sh_ph_prx_inj_d9_l_urdf.stl" scale="0.001 0.001 0.001"/>
      </geometry>
      <material name="qbshin/knuckle"/>
    </visual>
    <collision>
      <origin rpy="0 0 0" xyz="0 0 0"/>
      <geometry>
        <mesh filename="package://meshes/sh_ph_prx_inj_d9_l_urdf.stl" scale="0.001 0.001 0.001"/>
      </geometry>
    </collision>
  </link>
  <gazebo reference="qbshin_index_knuckle_link">
    <self_collide>1</self_collide>
    <!-- TODO: add other Gazebo Link properties (http://sdformat.org/spec?elem=link) -->
    <!--      <collision>-->
    <!--        <surface>-->
    <!--          <contact>-->
    <!--            <ode>-->
    <!--              <kp>1.0</kp>-->
    <!--              <kd>0.01</kd>-->
    <!--              <max_vel>0.0</max_vel>-->
    <!--              <min_depth>0.001</min_depth>-->
    <!--            </ode>-->
    <!--          </contact>-->
    <!--          <friction>-->
    <!--            <ode>-->
    <!--              <mu>0.9</mu>-->
    <!--              <mu2>0.9</mu2>-->
    <!--            </ode>-->
    <!--          </friction>-->
    <!--        </surface>-->
    <!--      </collision>-->
  </gazebo>
  <joint name="qbshin_index_proximal_joint" type="revolute">
    <origin rpy="0.0 0.0 0.0" xyz="0.01 0 0.002"/>
    <parent link="qbshin_index_knuckle_link"/>
    <child link="qbshin_index_proximal_virtual_link"/>
    <axis xyz="0 0 -1"/>
    <dynamics damping="0.0" friction="0.0"/>
    <limit effort="100" lower="0.0" upper="0.785" velocity="100"/>
    <mimic joint="qbshin_synergy_joint" multiplier="0.785"/>
  </joint>
  <transmission name="qbshin_transmission">
    <type>transmission_interface/qbMoveTransmission</type>
    <joint name="qbshin_index_proximal_joint">
      <hardwareInterface>hardware_interface/EffortJointInterface</hardwareInterface>
    </joint>
    <actuator name="qbshin_index_proximal_joint">
      <hardwareInterface>hardware_interface/EffortJointInterface</hardwareInterface>
    </actuator>
  </transmission>
  <gazebo reference="qbshin_index_proximal_joint">
    <!-- TODO: add other Gazebo Joint properties (http://sdformat.org/spec?elem=joint) -->
  </gazebo>
  <link name="qbshin_index_proximal_virtual_link">
    <inertial>
      <origin rpy="0 0 0" xyz="0 0 0"/>
      <mass value="1e-4"/>
      <inertia ixx="1e-9" ixy="0.0" ixz="0.0" iyy="1e-9" iyz="0.0" izz="1e-9"/>
    </inertial>
  </link>
  <joint name="qbshin_index_proximal_virtual_joint" type="revolute">
    <origin rpy="0 0 0" xyz="0.013 0 0"/>
    <parent link="qbshin_index_proximal_virtual_link"/>
    <child link="qbshin_index_proximal_link"/>
    <axis xyz="0 0 -1"/>
    <dynamics damping="0.0" friction="0.0"/>
    <limit effort="100" lower="0.0" upper="0.785" velocity="100"/>
    <mimic joint="qbshin_index_proximal_joint" multiplier="1.0"/>
  </joint>
  <transmission name="qbshin_transmission">
    <type>transmission_interface/qbMoveTransmission</type>
    <joint name="qbshin_index_proximal_virtual_joint">
      <hardwareInterface>hardware_interface/EffortJointInterface</hardwareInterface>
    </joint>
    <actuator name="qbshin_index_proximal_virtual_joint">
      <hardwareInterface>hardware_interface/EffortJointInterface</hardwareInterface>
    </actuator>
  </transmission>
  <gazebo reference="qbshin_index_proximal_virtual_joint">
    <!-- TODO: add other Gazebo Joint properties (http://sdformat.org/spec?elem=joint) -->
  </gazebo>
  <link name="qbshin_index_proximal_link">
    <inertial>
      <mass value="0.0082"/>
      <origin rpy="0 0 0" xyz="8.7707437e-03 -1.7863138e-03 0.0"/>
      <inertia ixx="2.2722068e-07" ixy="1.1586053e-08" ixz="0.0" iyy="5.5947233e-07" iyz="0.0" izz="5.9562195e-07"/>
    </inertial>
    <visual>
      <origin rpy="0 0 0" xyz="0 0 0"/>
      <geometry>
        <mesh filename="package://meshes/mc_h_pad_30_urdf.stl" scale="0.001 0.001 0.001"/>
      </geometry>
      <material name="qbshin/proximal"/>
    </visual>
    <collision>
      <origin rpy="0 0 0" xyz="0 0 0"/>
      <geometry>
        <mesh filename="package://meshes/mc_h_pad_30_urdf.stl" scale="0.001 0.001 0.001"/>
      </geometry>
    </collision>
  </link>
  <gazebo reference="qbshin_index_proximal_link">
    <self_collide>1</self_collide>
    <!-- TODO: add other Gazebo Link properties (http://sdformat.org/spec?elem=link) -->
    <!--      <collision>-->
    <!--        <surface>-->
    <!--          <contact>-->
    <!--            <ode>-->
    <!--              <kp>1.0</kp>-->
    <!--              <kd>0.01</kd>-->
    <!--              <max_vel>0.0</max_vel>-->
    <!--              <min_depth>0.001</min_depth>-->
    <!--            </ode>-->
    <!--          </contact>-->
    <!--          <friction>-->
    <!--            <ode>-->
    <!--              <mu>0.9</mu>-->
    <!--              <mu2>0.9</mu2>-->
    <!--            </ode>-->
    <!--          </friction>-->
    <!--        </surface>-->
    <!--      </collision>-->
  </gazebo>
  <joint name="qbshin_index_middle_joint" type="revolute">
    <origin rpy="0 0 0" xyz="0.017 0 0"/>
    <parent link="qbshin_index_proximal_link"/>
    <child link="qbshin_index_middle_virtual_link"/>
    <axis xyz="0 0 -1"/>
    <dynamics damping="0.0" friction="0.0"/>
    <limit effort="100" lower="0.0" upper="0.785" velocity="100"/>
    <mimic joint="qbshin_synergy_joint" multiplier="0.785"/>
  </joint>
  <transmission name="qbshin_transmission">
    <type>transmission_interface/qbMoveTransmission</type>
    <joint name="qbshin_index_middle_joint">
      <hardwareInterface>hardware_interface/EffortJointInterface</hardwareInterface>
    </joint>
    <actuator name="qbshin_index_middle_joint">
      <hardwareInterface>hardware_interface/EffortJointInterface</hardwareInterface>
    </actuator>
  </transmission>
  <gazebo reference="qbshin_index_middle_joint">
    <!-- TODO: add other Gazebo Joint properties (http://sdformat.org/spec?elem=joint) -->
  </gazebo>
  <link name="qbshin_index_middle_virtual_link">
    <inertial>
      <origin rpy="0 0 0" xyz="0 0 0"/>
      <mass value="1e-4"/>
      <inertia ixx="1e-9" ixy="0.0" ixz="0.0" iyy="1e-9" iyz="0.0" izz="1e-9"/>
    </inertial>
  </link>
  <joint name="qbshin_index_middle_virtual_joint" type="revolute">
    <origin rpy="0 0 0" xyz="0.013 0 0"/>
    <parent link="qbshin_index_middle_virtual_link"/>
    <child link="qbshin_index_middle_link"/>
    <axis xyz="0 0 -1"/>
    <dynamics damping="0.0" friction="0.0"/>
    <limit effort="100" lower="0.0" upper="0.785" velocity="100"/>
    <mimic joint="qbshin_index_middle_joint" multiplier="1.0"/>
  </joint>
  <transmission name="qbshin_transmission">
    <type>transmission_interface/qbMoveTransmission</type>
    <joint name="qbshin_index_middle_virtual_joint">
      <hardwareInterface>hardware_interface/EffortJointInterface</hardwareInterface>
    </joint>
    <actuator name="qbshin_index_middle_virtual_joint">
      <hardwareInterface>hardware_interface/EffortJointInterface</hardwareInterface>
    </actuator>
  </transmission>
  <gazebo reference="qbshin_index_middle_virtual_joint">
    <!-- TODO: add other Gazebo Joint properties (http://sdformat.org/spec?elem=joint) -->
  </gazebo>
  <link name="qbshin_index_middle_link">
    <inertial>
      <mass value="0.0082"/>
      <origin rpy="0 0 0" xyz="8.7707437e-03 -1.7863138e-03 0.0"/>
      <inertia ixx="2.2722068e-07" ixy="1.1586053e-08" ixz="0.0" iyy="5.5947233e-07" iyz="0.0" izz="5.9562195e-07"/>
    </inertial>
    <visual>
      <origin rpy="0 0 0" xyz="0 0 0"/>
      <geometry>
        <mesh filename="package://meshes/mc_h_pad_25_urdf.stl" scale="0.001 0.001 0.001"/>
      </geometry>
      <material name="qbshin/middle"/>
    </visual>
    <collision>
      <origin rpy="0 0 0" xyz="0 0 0"/>
      <geometry>
        <mesh filename="package://meshes/mc_h_pad_25_urdf.stl" scale="0.001 0.001 0.001"/>
      </geometry>
    </collision>
  </link>
  <gazebo reference="qbshin_index_middle_link">
    <self_collide>1</self_collide>
    <!-- TODO: add other Gazebo Link properties (http://sdformat.org/spec?elem=link) -->
    <!--      <collision>-->
    <!--        <surface>-->
    <!--          <contact>-->
    <!--            <ode>-->
    <!--              <kp>1.0</kp>-->
    <!--              <kd>0.01</kd>-->
    <!--              <max_vel>0.0</max_vel>-->
    <!--              <min_depth>0.001</min_depth>-->
    <!--            </ode>-->
    <!--          </contact>-->
    <!--          <friction>-->
    <!--            <ode>-->
    <!--              <mu>0.9</mu>-->
    <!--              <mu2>0.9</mu2>-->
    <!--            </ode>-->
    <!--          </friction>-->
    <!--        </surface>-->
    <!--      </collision>-->
  </gazebo>
  <joint name="qbshin_index_distal_joint" type="revolute">
    <origin rpy="0.0 0.0 0.0" xyz="0.012 0.002 0"/>
    <parent link="qbshin_index_middle_link"/>
    <child link="qbshin_index_distal_virtual_link"/>
    <axis xyz="0 0 -1"/>
    <dynamics damping="0.0" friction="0.0"/>
    <limit effort="100" lower="0.0" upper="0.785" velocity="100"/>
    <mimic joint="qbshin_synergy_joint" multiplier="0.785"/>
  </joint>
  <transmission name="qbshin_transmission">
    <type>transmission_interface/qbMoveTransmission</type>
    <joint name="qbshin_index_distal_joint">
      <hardwareInterface>hardware_interface/EffortJointInterface</hardwareInterface>
    </joint>
    <actuator name="qbshin_index_distal_joint">
      <hardwareInterface>hardware_interface/EffortJointInterface</hardwareInterface>
    </actuator>
  </transmission>
  <gazebo reference="qbshin_index_distal_joint">
    <!-- TODO: add other Gazebo Joint properties (http://sdformat.org/spec?elem=joint) -->
  </gazebo>
  <link name="qbshin_index_distal_virtual_link">
    <inertial>
      <origin rpy="0 0 0" xyz="0 0 0"/>
      <mass value="1e-4"/>
      <inertia ixx="1e-9" ixy="0.0" ixz="0.0" iyy="1e-9" iyz="0.0" izz="1e-9"/>
    </inertial>
  </link>
  <joint name="qbshin_index_distal_virtual_joint" type="revolute">
    <origin rpy="0 0 0" xyz="0.013 0 0"/>
    <parent link="qbshin_index_distal_virtual_link"/>
    <child link="qbshin_index_distal_link"/>
    <axis xyz="0 0 -1"/>
    <dynamics damping="0.0" friction="0.0"/>
    <limit effort="100" lower="0.0" upper="0.785" velocity="100"/>
    <mimic joint="qbshin_index_distal_joint" multiplier="1.0"/>
  </joint>
  <transmission name="qbshin_transmission">
    <type>transmission_interface/qbMoveTransmission</type>
    <joint name="qbshin_index_distal_virtual_joint">
      <hardwareInterface>hardware_interface/EffortJointInterface</hardwareInterface>
    </joint>
    <actuator name="qbshin_index_distal_virtual_joint">
      <hardwareInterface>hardware_interface/EffortJointInterface</hardwareInterface>
    </actuator>
  </transmission>
  <gazebo reference="qbshin_index_distal_virtual_joint">
    <!-- TODO: add other Gazebo Joint properties (http://sdformat.org/spec?elem=joint) -->
  </gazebo>
  <link name="qbshin_index_distal_link">
    <inertial>
      <mass value="0.009"/>
      <origin rpy="0 0 0" xyz="8.8025467e-03 -1.7219289e-03 0.0"/>
      <inertia ixx="2.6586142e-07" ixy="1.2416847e-08" ixz="0.0" iyy="5.9935767e-07" iyz="0.0" izz="6.6781963e-07"/>
    </inertial>
    <visual>
      <origin rpy="0 0 0" xyz="0 0 0"/>
      <geometry>
        <mesh filename="package://meshes/mc_h_pad_dist_urdf.stl" scale="0.001 0.001 0.001"/>
      </geometry>
      <material name="qbshin/distal"/>
    </visual>
    <collision>
      <origin rpy="0 0 0" xyz="0 0 0"/>
      <geometry>
        <mesh filename="package://meshes/mc_h_pad_dist_urdf.stl" scale="0.001 0.001 0.001"/>
      </geometry>
    </collision>
  </link>
  <gazebo reference="qbshin_index_distal_link">
    <self_collide>1</self_collide>
    <!-- TODO: add other Gazebo Link properties (http://sdformat.org/spec?elem=link) -->
    <!--      <collision>-->
    <!--        <surface>-->
    <!--          <contact>-->
    <!--            <ode>-->
    <!--              <kp>1.0</kp>-->
    <!--              <kd>0.01</kd>-->
    <!--              <max_vel>0.0</max_vel>-->
    <!--              <min_depth>0.001</min_depth>-->
    <!--            </ode>-->
    <!--          </contact>-->
    <!--          <friction>-->
    <!--            <ode>-->
    <!--              <mu>0.9</mu>-->
    <!--              <mu2>0.9</mu2>-->
    <!--            </ode>-->
    <!--          </friction>-->
    <!--        </surface>-->
    <!--      </collision>-->
  </gazebo>
  <joint name="qbshin_middle_knuckle_joint" type="revolute">
    <origin rpy="1.57 0 1.57" xyz="-0.005 0.068 -0.022"/>
    <parent link="qbshin_palm_link"/>
    <child link="qbshin_middle_knuckle_link"/>
    <axis xyz="0 0 -1"/>
    <dynamics damping="0.0" friction="0.0"/>
    <limit effort="100" lower="-0.524" upper="0.524" velocity="100"/>
    <mimic joint="qbshin_synergy_joint" multiplier="0.0"/>
  </joint>
  <transmission name="qbshin_transmission">
    <type>transmission_interface/qbMoveTransmission</type>
    <joint name="qbshin_middle_knuckle_joint">
      <hardwareInterface>hardware_interface/EffortJointInterface</hardwareInterface>
    </joint>
    <actuator name="qbshin_middle_knuckle_joint">
      <hardwareInterface>hardware_interface/EffortJointInterface</hardwareInterface>
    </actuator>
  </transmission>
  <gazebo reference="qbshin_middle_knuckle_joint">
    <!-- TODO: add other Gazebo Joint properties (http://sdformat.org/spec?elem=joint) -->
  </gazebo>
  <link name="qbshin_middle_knuckle_link">
    <inertial>
      <mass value="0.0095"/>
      <origin rpy="0 0 0" xyz="4.2753603e-04  0.0 -1.4321738e-03"/>
      <inertia ixx="6.4337303e-07" ixy="0.0" ixz="-3.9373913e-08" iyy="1.1253771e-06" iyz="0.0" izz="7.2336948e-07"/>
    </inertial>
    <visual>
      <origin rpy="0 0 0" xyz="0 0 0"/>
      <geometry>
        <mesh filename="package://meshes/sh_ph_prx_inj_d9_m_urdf.stl" scale="0.001 0.001 0.001"/>
      </geometry>
      <material name="qbshin/knuckle"/>
    </visual>
    <collision>
      <origin rpy="0 0 0" xyz="0 0 0"/>
      <geometry>
        <mesh filename="package://meshes/sh_ph_prx_inj_d9_m_urdf.stl" scale="0.001 0.001 0.001"/>
      </geometry>
    </collision>
  </link>
  <gazebo reference="qbshin_middle_knuckle_link">
    <self_collide>1</self_collide>
    <!-- TODO: add other Gazebo Link properties (http://sdformat.org/spec?elem=link) -->
    <!--      <collision>-->
    <!--        <surface>-->
    <!--          <contact>-->
    <!--            <ode>-->
    <!--              <kp>1.0</kp>-->
    <!--              <kd>0.01</kd>-->
    <!--              <max_vel>0.0</max_vel>-->
    <!--              <min_depth>0.001</min_depth>-->
    <!--            </ode>-->
    <!--          </contact>-->
    <!--          <friction>-->
    <!--            <ode>-->
    <!--              <mu>0.9</mu>-->
    <!--              <mu2>0.9</mu2>-->
    <!--            </ode>-->
    <!--          </friction>-->
    <!--        </surface>-->
    <!--      </collision>-->
  </gazebo>
  <joint name="qbshin_middle_proximal_joint" type="revolute">
    <origin rpy="0.0 0.0 0.0" xyz="0.01 0 0"/>
    <parent link="qbshin_middle_knuckle_link"/>
    <child link="qbshin_middle_proximal_virtual_link"/>
    <axis xyz="0 0 -1"/>
    <dynamics damping="0.0" friction="0.0"/>
    <limit effort="100" lower="0.0" upper="0.785" velocity="100"/>
    <mimic joint="qbshin_synergy_joint" multiplier="0.785"/>
  </joint>
  <transmission name="qbshin_transmission">
    <type>transmission_interface/qbMoveTransmission</type>
    <joint name="qbshin_middle_proximal_joint">
      <hardwareInterface>hardware_interface/EffortJointInterface</hardwareInterface>
    </joint>
    <actuator name="qbshin_middle_proximal_joint">
      <hardwareInterface>hardware_interface/EffortJointInterface</hardwareInterface>
    </actuator>
  </transmission>
  <gazebo reference="qbshin_middle_proximal_joint">
    <!-- TODO: add other Gazebo Joint properties (http://sdformat.org/spec?elem=joint) -->
  </gazebo>
  <link name="qbshin_middle_proximal_virtual_link">
    <inertial>
      <origin rpy="0 0 0" xyz="0 0 0"/>
      <mass value="1e-4"/>
      <inertia ixx="1e-9" ixy="0.0" ixz="0.0" iyy="1e-9" iyz="0.0" izz="1e-9"/>
    </inertial>
  </link>
  <joint name="qbshin_middle_proximal_virtual_joint" type="revolute">
    <origin rpy="0 0 0" xyz="0.013 0 0"/>
    <parent link="qbshin_middle_proximal_virtual_link"/>
    <child link="qbshin_middle_proximal_link"/>
    <axis xyz="0 0 -1"/>
    <dynamics damping="0.0" friction="0.0"/>
    <limit effort="100" lower="0.0" upper="0.785" velocity="100"/>
    <mimic joint="qbshin_middle_proximal_joint" multiplier="1.0"/>
  </joint>
  <transmission name="qbshin_transmission">
    <type>transmission_interface/qbMoveTransmission</type>
    <joint name="qbshin_middle_proximal_virtual_joint">
      <hardwareInterface>hardware_interface/EffortJointInterface</hardwareInterface>
    </joint>
    <actuator name="qbshin_middle_proximal_virtual_joint">
      <hardwareInterface>hardware_interface/EffortJointInterface</hardwareInterface>
    </actuator>
  </transmission>
  <gazebo reference="qbshin_middle_proximal_virtual_joint">
    <!-- TODO: add other Gazebo Joint properties (http://sdformat.org/spec?elem=joint) -->
  </gazebo>
  <link name="qbshin_middle_proximal_link">
    <inertial>
      <mass value="0.0082"/>
      <origin rpy="0 0 0" xyz="8.7707437e-03 -1.7863138e-03 0.0"/>
      <inertia ixx="2.2722068e-07" ixy="1.1586053e-08" ixz="0.0" iyy="5.5947233e-07" iyz="0.0" izz="5.9562195e-07"/>
    </inertial>
    <visual>
      <origin rpy="0 0 0" xyz="0 0 0"/>
      <geometry>
        <mesh filename="package://meshes/mc_h_pad_30_urdf.stl" scale="0.001 0.001 0.001"/>
      </geometry>
      <material name="qbshin/proximal"/>
    </visual>
    <collision>
      <origin rpy="0 0 0" xyz="0 0 0"/>
      <geometry>
        <mesh filename="package://meshes/mc_h_pad_30_urdf.stl" scale="0.001 0.001 0.001"/>
      </geometry>
    </collision>
  </link>
  <gazebo reference="qbshin_middle_proximal_link">
    <self_collide>1</self_collide>
    <!-- TODO: add other Gazebo Link properties (http://sdformat.org/spec?elem=link) -->
    <!--      <collision>-->
    <!--        <surface>-->
    <!--          <contact>-->
    <!--            <ode>-->
    <!--              <kp>1.0</kp>-->
    <!--              <kd>0.01</kd>-->
    <!--              <max_vel>0.0</max_vel>-->
    <!--              <min_depth>0.001</min_depth>-->
    <!--            </ode>-->
    <!--          </contact>-->
    <!--          <friction>-->
    <!--            <ode>-->
    <!--              <mu>0.9</mu>-->
    <!--              <mu2>0.9</mu2>-->
    <!--            </ode>-->
    <!--          </friction>-->
    <!--        </surface>-->
    <!--      </collision>-->
  </gazebo>
  <joint name="qbshin_middle_middle_joint" type="revolute">
    <origin rpy="0 0 0" xyz="0.017 0 0"/>
    <parent link="qbshin_middle_proximal_link"/>
    <child link="qbshin_middle_middle_virtual_link"/>
    <axis xyz="0 0 -1"/>
    <dynamics damping="0.0" friction="0.0"/>
    <limit effort="100" lower="0.0" upper="0.785" velocity="100"/>
    <mimic joint="qbshin_synergy_joint" multiplier="0.785"/>
  </joint>
  <transmission name="qbshin_transmission">
    <type>transmission_interface/qbMoveTransmission</type>
    <joint name="qbshin_middle_middle_joint">
      <hardwareInterface>hardware_interface/EffortJointInterface</hardwareInterface>
    </joint>
    <actuator name="qbshin_middle_middle_joint">
      <hardwareInterface>hardware_interface/EffortJointInterface</hardwareInterface>
    </actuator>
  </transmission>
  <gazebo reference="qbshin_middle_middle_joint">
    <!-- TODO: add other Gazebo Joint properties (http://sdformat.org/spec?elem=joint) -->
  </gazebo>
  <link name="qbshin_middle_middle_virtual_link">
    <inertial>
      <origin rpy="0 0 0" xyz="0 0 0"/>
      <mass value="1e-4"/>
      <inertia ixx="1e-9" ixy="0.0" ixz="0.0" iyy="1e-9" iyz="0.0" izz="1e-9"/>
    </inertial>
  </link>
  <joint name="qbshin_middle_middle_virtual_joint" type="revolute">
    <origin rpy="0 0 0" xyz="0.013 0 0"/>
    <parent link="qbshin_middle_middle_virtual_link"/>
    <child link="qbshin_middle_middle_link"/>
    <axis xyz="0 0 -1"/>
    <dynamics damping="0.0" friction="0.0"/>
    <limit effort="100" lower="0.0" upper="0.785" velocity="100"/>
    <mimic joint="qbshin_middle_middle_joint" multiplier="1.0"/>
  </joint>
  <transmission name="qbshin_transmission">
    <type>transmission_interface/qbMoveTransmission</type>
    <joint name="qbshin_middle_middle_virtual_joint">
      <hardwareInterface>hardware_interface/EffortJointInterface</hardwareInterface>
    </joint>
    <actuator name="qbshin_middle_middle_virtual_joint">
      <hardwareInterface>hardware_interface/EffortJointInterface</hardwareInterface>
    </actuator>
  </transmission>
  <gazebo reference="qbshin_middle_middle_virtual_joint">
    <!-- TODO: add other Gazebo Joint properties (http://sdformat.org/spec?elem=joint) -->
  </gazebo>
  <link name="qbshin_middle_middle_link">
    <inertial>
      <mass value="0.0082"/>
      <origin rpy="0 0 0" xyz="8.7707437e-03 -1.7863138e-03 0.0"/>
      <inertia ixx="2.2722068e-07" ixy="1.1586053e-08" ixz="0.0" iyy="5.5947233e-07" iyz="0.0" izz="5.9562195e-07"/>
    </inertial>
    <visual>
      <origin rpy="0 0 0" xyz="0 0 0"/>
      <geometry>
        <mesh filename="package://meshes/mc_h_pad_30_urdf.stl" scale="0.001 0.001 0.001"/>
      </geometry>
      <material name="qbshin/middle"/>
    </visual>
    <collision>
      <origin rpy="0 0 0" xyz="0 0 0"/>
      <geometry>
        <mesh filename="package://meshes/mc_h_pad_30_urdf.stl" scale="0.001 0.001 0.001"/>
      </geometry>
    </collision>
  </link>
  <gazebo reference="qbshin_middle_middle_link">
    <self_collide>1</self_collide>
    <!-- TODO: add other Gazebo Link properties (http://sdformat.org/spec?elem=link) -->
    <!--      <collision>-->
    <!--        <surface>-->
    <!--          <contact>-->
    <!--            <ode>-->
    <!--              <kp>1.0</kp>-->
    <!--              <kd>0.01</kd>-->
    <!--              <max_vel>0.0</max_vel>-->
    <!--              <min_depth>0.001</min_depth>-->
    <!--            </ode>-->
    <!--          </contact>-->
    <!--          <friction>-->
    <!--            <ode>-->
    <!--              <mu>0.9</mu>-->
    <!--              <mu2>0.9</mu2>-->
    <!--            </ode>-->
    <!--          </friction>-->
    <!--        </surface>-->
    <!--      </collision>-->
  </gazebo>
  <joint name="qbshin_middle_distal_joint" type="revolute">
    <origin rpy="0.0 0.0 0.0" xyz="0.014 0.002 0"/>
    <parent link="qbshin_middle_middle_link"/>
    <child link="qbshin_middle_distal_virtual_link"/>
    <axis xyz="0 0 -1"/>
    <dynamics damping="0.0" friction="0.0"/>
    <limit effort="100" lower="0.0" upper="0.785" velocity="100"/>
    <mimic joint="qbshin_synergy_joint" multiplier="0.785"/>
  </joint>
  <transmission name="qbshin_transmission">
    <type>transmission_interface/qbMoveTransmission</type>
    <joint name="qbshin_middle_distal_joint">
      <hardwareInterface>hardware_interface/EffortJointInterface</hardwareInterface>
    </joint>
    <actuator name="qbshin_middle_distal_joint">
      <hardwareInterface>hardware_interface/EffortJointInterface</hardwareInterface>
    </actuator>
  </transmission>
  <gazebo reference="qbshin_middle_distal_joint">
    <!-- TODO: add other Gazebo Joint properties (http://sdformat.org/spec?elem=joint) -->
  </gazebo>
  <link name="qbshin_middle_distal_virtual_link">
    <inertial>
      <origin rpy="0 0 0" xyz="0 0 0"/>
      <mass value="1e-4"/>
      <inertia ixx="1e-9" ixy="0.0" ixz="0.0" iyy="1e-9" iyz="0.0" izz="1e-9"/>
    </inertial>
  </link>
  <joint name="qbshin_middle_distal_virtual_joint" type="revolute">
    <origin rpy="0 0 0" xyz="0.013 0 0"/>
    <parent link="qbshin_middle_distal_virtual_link"/>
    <child link="qbshin_middle_distal_link"/>
    <axis xyz="0 0 -1"/>
    <dynamics damping="0.0" friction="0.0"/>
    <limit effort="100" lower="0.0" upper="0.785" velocity="100"/>
    <mimic joint="qbshin_middle_distal_joint" multiplier="1.0"/>
  </joint>
  <transmission name="qbshin_transmission">
    <type>transmission_interface/qbMoveTransmission</type>
    <joint name="qbshin_middle_distal_virtual_joint">
      <hardwareInterface>hardware_interface/EffortJointInterface</hardwareInterface>
    </joint>
    <actuator name="qbshin_middle_distal_virtual_joint">
      <hardwareInterface>hardware_interface/EffortJointInterface</hardwareInterface>
    </actuator>
  </transmission>
  <gazebo reference="qbshin_middle_distal_virtual_joint">
    <!-- TODO: add other Gazebo Joint properties (http://sdformat.org/spec?elem=joint) -->
  </gazebo>
  <link name="qbshin_middle_distal_link">
    <inertial>
      <mass value="0.009"/>
      <origin rpy="0 0 0" xyz="8.8025467e-03 -1.7219289e-03 0.0"/>
      <inertia ixx="2.6586142e-07" ixy="1.2416847e-08" ixz="0.0" iyy="5.9935767e-07" iyz="0.0" izz="6.6781963e-07"/>
    </inertial>
    <visual>
      <origin rpy="0 0 0" xyz="0 0 0"/>
      <geometry>
        <mesh filename="package://meshes/mc_h_pad_dist_urdf.stl" scale="0.001 0.001 0.001"/>
      </geometry>
      <material name="qbshin/distal"/>
    </visual>
    <collision>
      <origin rpy="0 0 0" xyz="0 0 0"/>
      <geometry>
        <mesh filename="package://meshes/mc_h_pad_dist_urdf.stl" scale="0.001 0.001 0.001"/>
      </geometry>
    </collision>
  </link>
  <gazebo reference="qbshin_middle_distal_link">
    <self_collide>1</self_collide>
    <!-- TODO: add other Gazebo Link properties (http://sdformat.org/spec?elem=link) -->
    <!--      <collision>-->
    <!--        <surface>-->
    <!--          <contact>-->
    <!--            <ode>-->
    <!--              <kp>1.0</kp>-->
    <!--              <kd>0.01</kd>-->
    <!--              <max_vel>0.0</max_vel>-->
    <!--              <min_depth>0.001</min_depth>-->
    <!--            </ode>-->
    <!--          </contact>-->
    <!--          <friction>-->
    <!--            <ode>-->
    <!--              <mu>0.9</mu>-->
    <!--              <mu2>0.9</mu2>-->
    <!--            </ode>-->
    <!--          </friction>-->
    <!--        </surface>-->
    <!--      </collision>-->
  </gazebo>
  <joint name="qbshin_ring_knuckle_joint" type="revolute">
    <origin rpy="1.57 0 1.57" xyz="0.022 0.062 -0.022"/>
    <parent link="qbshin_palm_link"/>
    <child link="qbshin_ring_knuckle_link"/>
    <axis xyz="0 0 -1"/>
    <dynamics damping="0.0" friction="0.0"/>
    <limit effort="100" lower="-0.524" upper="0.524" velocity="100"/>
    <mimic joint="qbshin_synergy_joint" multiplier="0.2"/>
  </joint>
  <transmission name="qbshin_transmission">
    <type>transmission_interface/qbMoveTransmission</type>
    <joint name="qbshin_ring_knuckle_joint">
      <hardwareInterface>hardware_interface/EffortJointInterface</hardwareInterface>
    </joint>
    <actuator name="qbshin_ring_knuckle_joint">
      <hardwareInterface>hardware_interface/EffortJointInterface</hardwareInterface>
    </actuator>
  </transmission>
  <gazebo reference="qbshin_ring_knuckle_joint">
    <!-- TODO: add other Gazebo Joint properties (http://sdformat.org/spec?elem=joint) -->
  </gazebo>
  <link name="qbshin_ring_knuckle_link">
    <inertial>
      <mass value="0.0095"/>
      <origin rpy="0 0 0" xyz="4.2753603e-04  0.0 -1.4321738e-03"/>
      <inertia ixx="6.4337303e-07" ixy="0.0" ixz="-3.9373913e-08" iyy="1.1253771e-06" iyz="0.0" izz="7.2336948e-07"/>
    </inertial>
    <visual>
      <origin rpy="0 0 0" xyz="0 0 0"/>
      <geometry>
        <mesh filename="package://meshes/sh_ph_prx_inj_d9_r_urdf.stl" scale="0.001 0.001 0.001"/>
      </geometry>
      <material name="qbshin/knuckle"/>
    </visual>
    <collision>
      <origin rpy="0 0 0" xyz="0 0 0"/>
      <geometry>
        <mesh filename="package://meshes/sh_ph_prx_inj_d9_r_urdf.stl" scale="0.001 0.001 0.001"/>
      </geometry>
    </collision>
  </link>
  <gazebo reference="qbshin_ring_knuckle_link">
    <self_collide>1</self_collide>
    <!-- TODO: add other Gazebo Link properties (http://sdformat.org/spec?elem=link) -->
    <!--      <collision>-->
    <!--        <surface>-->
    <!--          <contact>-->
    <!--            <ode>-->
    <!--              <kp>1.0</kp>-->
    <!--              <kd>0.01</kd>-->
    <!--              <max_vel>0.0</max_vel>-->
    <!--              <min_depth>0.001</min_depth>-->
    <!--            </ode>-->
    <!--          </contact>-->
    <!--          <friction>-->
    <!--            <ode>-->
    <!--              <mu>0.9</mu>-->
    <!--              <mu2>0.9</mu2>-->
    <!--            </ode>-->
    <!--          </friction>-->
    <!--        </surface>-->
    <!--      </collision>-->
  </gazebo>
  <joint name="qbshin_ring_proximal_joint" type="revolute">
    <origin rpy="0.0 0.0 0.0" xyz="0.01 0 -0.002"/>
    <parent link="qbshin_ring_knuckle_link"/>
    <child link="qbshin_ring_proximal_virtual_link"/>
    <axis xyz="0 0 -1"/>
    <dynamics damping="0.0" friction="0.0"/>
    <limit effort="100" lower="0.0" upper="0.785" velocity="100"/>
    <mimic joint="qbshin_synergy_joint" multiplier="0.785"/>
  </joint>
  <transmission name="qbshin_transmission">
    <type>transmission_interface/qbMoveTransmission</type>
    <joint name="qbshin_ring_proximal_joint">
      <hardwareInterface>hardware_interface/EffortJointInterface</hardwareInterface>
    </joint>
    <actuator name="qbshin_ring_proximal_joint">
      <hardwareInterface>hardware_interface/EffortJointInterface</hardwareInterface>
    </actuator>
  </transmission>
  <gazebo reference="qbshin_ring_proximal_joint">
    <!-- TODO: add other Gazebo Joint properties (http://sdformat.org/spec?elem=joint) -->
  </gazebo>
  <link name="qbshin_ring_proximal_virtual_link">
    <inertial>
      <origin rpy="0 0 0" xyz="0 0 0"/>
      <mass value="1e-4"/>
      <inertia ixx="1e-9" ixy="0.0" ixz="0.0" iyy="1e-9" iyz="0.0" izz="1e-9"/>
    </inertial>
  </link>
  <joint name="qbshin_ring_proximal_virtual_joint" type="revolute">
    <origin rpy="0 0 0" xyz="0.013 0 0"/>
    <parent link="qbshin_ring_proximal_virtual_link"/>
    <child link="qbshin_ring_proximal_link"/>
    <axis xyz="0 0 -1"/>
    <dynamics damping="0.0" friction="0.0"/>
    <limit effort="100" lower="0.0" upper="0.785" velocity="100"/>
    <mimic joint="qbshin_ring_proximal_joint" multiplier="1.0"/>
  </joint>
  <transmission name="qbshin_transmission">
    <type>transmission_interface/qbMoveTransmission</type>
    <joint name="qbshin_ring_proximal_virtual_joint">
      <hardwareInterface>hardware_interface/EffortJointInterface</hardwareInterface>
    </joint>
    <actuator name="qbshin_ring_proximal_virtual_joint">
      <hardwareInterface>hardware_interface/EffortJointInterface</hardwareInterface>
    </actuator>
  </transmission>
  <gazebo reference="qbshin_ring_proximal_virtual_joint">
    <!-- TODO: add other Gazebo Joint properties (http://sdformat.org/spec?elem=joint) -->
  </gazebo>
  <link name="qbshin_ring_proximal_link">
    <inertial>
      <mass value="0.0082"/>
      <origin rpy="0 0 0" xyz="8.7707437e-03 -1.7863138e-03 0.0"/>
      <inertia ixx="2.2722068e-07" ixy="1.1586053e-08" ixz="0.0" iyy="5.5947233e-07" iyz="0.0" izz="5.9562195e-07"/>
    </inertial>
    <visual>
      <origin rpy="0 0 0" xyz="0 0 0"/>
      <geometry>
        <mesh filename="package://meshes/mc_h_pad_30_urdf.stl" scale="0.001 0.001 0.001"/>
      </geometry>
      <material name="qbshin/proximal"/>
    </visual>
    <collision>
      <origin rpy="0 0 0" xyz="0 0 0"/>
      <geometry>
        <mesh filename="package://meshes/mc_h_pad_30_urdf.stl" scale="0.001 0.001 0.001"/>
      </geometry>
    </collision>
  </link>
  <gazebo reference="qbshin_ring_proximal_link">
    <self_collide>1</self_collide>
    <!-- TODO: add other Gazebo Link properties (http://sdformat.org/spec?elem=link) -->
    <!--      <collision>-->
    <!--        <surface>-->
    <!--          <contact>-->
    <!--            <ode>-->
    <!--              <kp>1.0</kp>-->
    <!--              <kd>0.01</kd>-->
    <!--              <max_vel>0.0</max_vel>-->
    <!--              <min_depth>0.001</min_depth>-->
    <!--            </ode>-->
    <!--          </contact>-->
    <!--          <friction>-->
    <!--            <ode>-->
    <!--              <mu>0.9</mu>-->
    <!--              <mu2>0.9</mu2>-->
    <!--            </ode>-->
    <!--          </friction>-->
    <!--        </surface>-->
    <!--      </collision>-->
  </gazebo>
  <joint name="qbshin_ring_middle_joint" type="revolute">
    <origin rpy="0 0 0" xyz="0.017 0 0"/>
    <parent link="qbshin_ring_proximal_link"/>
    <child link="qbshin_ring_middle_virtual_link"/>
    <axis xyz="0 0 -1"/>
    <dynamics damping="0.0" friction="0.0"/>
    <limit effort="100" lower="0.0" upper="0.785" velocity="100"/>
    <mimic joint="qbshin_synergy_joint" multiplier="0.785"/>
  </joint>
  <transmission name="qbshin_transmission">
    <type>transmission_interface/qbMoveTransmission</type>
    <joint name="qbshin_ring_middle_joint">
      <hardwareInterface>hardware_interface/EffortJointInterface</hardwareInterface>
    </joint>
    <actuator name="qbshin_ring_middle_joint">
      <hardwareInterface>hardware_interface/EffortJointInterface</hardwareInterface>
    </actuator>
  </transmission>
  <gazebo reference="qbshin_ring_middle_joint">
    <!-- TODO: add other Gazebo Joint properties (http://sdformat.org/spec?elem=joint) -->
  </gazebo>
  <link name="qbshin_ring_middle_virtual_link">
    <inertial>
      <origin rpy="0 0 0" xyz="0 0 0"/>
      <mass value="1e-4"/>
      <inertia ixx="1e-9" ixy="0.0" ixz="0.0" iyy="1e-9" iyz="0.0" izz="1e-9"/>
    </inertial>
  </link>
  <joint name="qbshin_ring_middle_virtual_joint" type="revolute">
    <origin rpy="0 0 0" xyz="0.013 0 0"/>
    <parent link="qbshin_ring_middle_virtual_link"/>
    <child link="qbshin_ring_middle_link"/>
    <axis xyz="0 0 -1"/>
    <dynamics damping="0.0" friction="0.0"/>
    <limit effort="100" lower="0.0" upper="0.785" velocity="100"/>
    <mimic joint="qbshin_ring_middle_joint" multiplier="1.0"/>
  </joint>
  <transmission name="qbshin_transmission">
    <type>transmission_interface/qbMoveTransmission</type>
    <joint name="qbshin_ring_middle_virtual_joint">
      <hardwareInterface>hardware_interface/EffortJointInterface</hardwareInterface>
    </joint>
    <actuator name="qbshin_ring_middle_virtual_joint">
      <hardwareInterface>hardware_interface/EffortJointInterface</hardwareInterface>
    </actuator>
  </transmission>
  <gazebo reference="qbshin_ring_middle_virtual_joint">
    <!-- TODO: add other Gazebo Joint properties (http://sdformat.org/spec?elem=joint) -->
  </gazebo>
  <link name="qbshin_ring_middle_link">
    <inertial>
      <mass value="0.0082"/>
      <origin rpy="0 0 0" xyz="8.7707437e-03 -1.7863138e-03 0.0"/>
      <inertia ixx="2.2722068e-07" ixy="1.1586053e-08" ixz="0.0" iyy="5.5947233e-07" iyz="0.0" izz="5.9562195e-07"/>
    </inertial>
    <visual>
      <origin rpy="0 0 0" xyz="0 0 0"/>
      <geometry>
        <mesh filename="package://meshes/mc_h_pad_25_urdf.stl" scale="0.001 0.001 0.001"/>
      </geometry>
      <material name="qbshin/middle"/>
    </visual>
    <collision>
      <origin rpy="0 0 0" xyz="0 0 0"/>
      <geometry>
        <mesh filename="package://meshes/mc_h_pad_25_urdf.stl" scale="0.001 0.001 0.001"/>
      </geometry>
    </collision>
  </link>
  <gazebo reference="qbshin_ring_middle_link">
    <self_collide>1</self_collide>
    <!-- TODO: add other Gazebo Link properties (http://sdformat.org/spec?elem=link) -->
    <!--      <collision>-->
    <!--        <surface>-->
    <!--          <contact>-->
    <!--            <ode>-->
    <!--              <kp>1.0</kp>-->
    <!--              <kd>0.01</kd>-->
    <!--              <max_vel>0.0</max_vel>-->
    <!--              <min_depth>0.001</min_depth>-->
    <!--            </ode>-->
    <!--          </contact>-->
    <!--          <friction>-->
    <!--            <ode>-->
    <!--              <mu>0.9</mu>-->
    <!--              <mu2>0.9</mu2>-->
    <!--            </ode>-->
    <!--          </friction>-->
    <!--        </surface>-->
    <!--      </collision>-->
  </gazebo>
  <joint name="qbshin_ring_distal_joint" type="revolute">
    <origin rpy="0.0 0.0 0.0" xyz="0.012 0.002 0"/>
    <parent link="qbshin_ring_middle_link"/>
    <child link="qbshin_ring_distal_virtual_link"/>
    <axis xyz="0 0 -1"/>
    <dynamics damping="0.0" friction="0.0"/>
    <limit effort="100" lower="0.0" upper="0.785" velocity="100"/>
    <mimic joint="qbshin_synergy_joint" multiplier="0.785"/>
  </joint>
  <transmission name="qbshin_transmission">
    <type>transmission_interface/qbMoveTransmission</type>
    <joint name="qbshin_ring_distal_joint">
      <hardwareInterface>hardware_interface/EffortJointInterface</hardwareInterface>
    </joint>
    <actuator name="qbshin_ring_distal_joint">
      <hardwareInterface>hardware_interface/EffortJointInterface</hardwareInterface>
    </actuator>
  </transmission>
  <gazebo reference="qbshin_ring_distal_joint">
    <!-- TODO: add other Gazebo Joint properties (http://sdformat.org/spec?elem=joint) -->
  </gazebo>
  <link name="qbshin_ring_distal_virtual_link">
    <inertial>
      <origin rpy="0 0 0" xyz="0 0 0"/>
      <mass value="1e-4"/>
      <inertia ixx="1e-9" ixy="0.0" ixz="0.0" iyy="1e-9" iyz="0.0" izz="1e-9"/>
    </inertial>
  </link>
  <joint name="qbshin_ring_distal_virtual_joint" type="revolute">
    <origin rpy="0 0 0" xyz="0.013 0 0"/>
    <parent link="qbshin_ring_distal_virtual_link"/>
    <child link="qbshin_ring_distal_link"/>
    <axis xyz="0 0 -1"/>
    <dynamics damping="0.0" friction="0.0"/>
    <limit effort="100" lower="0.0" upper="0.785" velocity="100"/>
    <mimic joint="qbshin_ring_distal_joint" multiplier="1.0"/>
  </joint>
  <transmission name="qbshin_transmission">
    <type>transmission_interface/qbMoveTransmission</type>
    <joint name="qbshin_ring_distal_virtual_joint">
      <hardwareInterface>hardware_interface/EffortJointInterface</hardwareInterface>
    </joint>
    <actuator name="qbshin_ring_distal_virtual_joint">
      <hardwareInterface>hardware_interface/EffortJointInterface</hardwareInterface>
    </actuator>
  </transmission>
  <gazebo reference="qbshin_ring_distal_virtual_joint">
    <!-- TODO: add other Gazebo Joint properties (http://sdformat.org/spec?elem=joint) -->
  </gazebo>
  <link name="qbshin_ring_distal_link">
    <inertial>
      <mass value="0.009"/>
      <origin rpy="0 0 0" xyz="8.8025467e-03 -1.7219289e-03 0.0"/>
      <inertia ixx="2.6586142e-07" ixy="1.2416847e-08" ixz="0.0" iyy="5.9935767e-07" iyz="0.0" izz="6.6781963e-07"/>
    </inertial>
    <visual>
      <origin rpy="0 0 0" xyz="0 0 0"/>
      <geometry>
        <mesh filename="package://meshes/mc_h_pad_dist_urdf.stl" scale="0.001 0.001 0.001"/>
      </geometry>
      <material name="qbshin/distal"/>
    </visual>
    <collision>
      <origin rpy="0 0 0" xyz="0 0 0"/>
      <geometry>
        <mesh filename="package://meshes/mc_h_pad_dist_urdf.stl" scale="0.001 0.001 0.001"/>
      </geometry>
    </collision>
  </link>
  <gazebo reference="qbshin_ring_distal_link">
    <self_collide>1</self_collide>
    <!-- TODO: add other Gazebo Link properties (http://sdformat.org/spec?elem=link) -->
    <!--      <collision>-->
    <!--        <surface>-->
    <!--          <contact>-->
    <!--            <ode>-->
    <!--              <kp>1.0</kp>-->
    <!--              <kd>0.01</kd>-->
    <!--              <max_vel>0.0</max_vel>-->
    <!--              <min_depth>0.001</min_depth>-->
    <!--            </ode>-->
    <!--          </contact>-->
    <!--          <friction>-->
    <!--            <ode>-->
    <!--              <mu>0.9</mu>-->
    <!--              <mu2>0.9</mu2>-->
    <!--            </ode>-->
    <!--          </friction>-->
    <!--        </surface>-->
    <!--      </collision>-->
  </gazebo>
  <joint name="qbshin_little_knuckle_joint" type="revolute">
    <origin rpy="1.57 0 1.57" xyz="0.049 0.044 -0.022"/>
    <parent link="qbshin_palm_link"/>
    <child link="qbshin_little_knuckle_link"/>
    <axis xyz="0 0 -1"/>
    <dynamics damping="0.0" friction="0.0"/>
    <limit effort="100" lower="-0.524" upper="0.524" velocity="100"/>
    <mimic joint="qbshin_synergy_joint" multiplier="0.4"/>
  </joint>
  <transmission name="qbshin_transmission">
    <type>transmission_interface/qbMoveTransmission</type>
    <joint name="qbshin_little_knuckle_joint">
      <hardwareInterface>hardware_interface/EffortJointInterface</hardwareInterface>
    </joint>
    <actuator name="qbshin_little_knuckle_joint">
      <hardwareInterface>hardware_interface/EffortJointInterface</hardwareInterface>
    </actuator>
  </transmission>
  <gazebo reference="qbshin_little_knuckle_joint">
    <!-- TODO: add other Gazebo Joint properties (http://sdformat.org/spec?elem=joint) -->
  </gazebo>
  <link name="qbshin_little_knuckle_link">
    <inertial>
      <mass value="0.0095"/>
      <origin rpy="0 0 0" xyz="4.2753603e-04  0.0 -1.4321738e-03"/>
      <inertia ixx="6.4337303e-07" ixy="0.0" ixz="-3.9373913e-08" iyy="1.1253771e-06" iyz="0.0" izz="7.2336948e-07"/>
    </inertial>
    <visual>
      <origin rpy="0 0 0" xyz="0 0 0"/>
      <geometry>
        <mesh filename="package://meshes/sh_ph_prx_inj_d9_r_urdf.stl" scale="0.001 0.001 0.001"/>
      </geometry>
      <material name="qbshin/knuckle"/>
    </visual>
    <collision>
      <origin rpy="0 0 0" xyz="0 0 0"/>
      <geometry>
        <mesh filename="package://meshes/sh_ph_prx_inj_d9_r_urdf.stl" scale="0.001 0.001 0.001"/>
      </geometry>
    </collision>
  </link>
  <gazebo reference="qbshin_little_knuckle_link">
    <self_collide>1</self_collide>
    <!-- TODO: add other Gazebo Link properties (http://sdformat.org/spec?elem=link) -->
    <!--      <collision>-->
    <!--        <surface>-->
    <!--          <contact>-->
    <!--            <ode>-->
    <!--              <kp>1.0</kp>-->
    <!--              <kd>0.01</kd>-->
    <!--              <max_vel>0.0</max_vel>-->
    <!--              <min_depth>0.001</min_depth>-->
    <!--            </ode>-->
    <!--          </contact>-->
    <!--          <friction>-->
    <!--            <ode>-->
    <!--              <mu>0.9</mu>-->
    <!--              <mu2>0.9</mu2>-->
    <!--            </ode>-->
    <!--          </friction>-->
    <!--        </surface>-->
    <!--      </collision>-->
  </gazebo>
  <joint name="qbshin_little_proximal_joint" type="revolute">
    <origin rpy="0.0 0.0 0.0" xyz="0.01 0 -0.002"/>
    <parent link="qbshin_little_knuckle_link"/>
    <child link="qbshin_little_proximal_virtual_link"/>
    <axis xyz="0 0 -1"/>
    <dynamics damping="0.0" friction="0.0"/>
    <limit effort="100" lower="0.0" upper="0.785" velocity="100"/>
    <mimic joint="qbshin_synergy_joint" multiplier="0.785"/>
  </joint>
  <transmission name="qbshin_transmission">
    <type>transmission_interface/qbMoveTransmission</type>
    <joint name="qbshin_little_proximal_joint">
      <hardwareInterface>hardware_interface/EffortJointInterface</hardwareInterface>
    </joint>
    <actuator name="qbshin_little_proximal_joint">
      <hardwareInterface>hardware_interface/EffortJointInterface</hardwareInterface>
    </actuator>
  </transmission>
  <gazebo reference="qbshin_little_proximal_joint">
    <!-- TODO: add other Gazebo Joint properties (http://sdformat.org/spec?elem=joint) -->
  </gazebo>
  <link name="qbshin_little_proximal_virtual_link">
    <inertial>
      <origin rpy="0 0 0" xyz="0 0 0"/>
      <mass value="1e-4"/>
      <inertia ixx="1e-9" ixy="0.0" ixz="0.0" iyy="1e-9" iyz="0.0" izz="1e-9"/>
    </inertial>
  </link>
  <joint name="qbshin_little_proximal_virtual_joint" type="revolute">
    <origin rpy="0 0 0" xyz="0.013 0 0"/>
    <parent link="qbshin_little_proximal_virtual_link"/>
    <child link="qbshin_little_proximal_link"/>
    <axis xyz="0 0 -1"/>
    <dynamics damping="0.0" friction="0.0"/>
    <limit effort="100" lower="0.0" upper="0.785" velocity="100"/>
    <mimic joint="qbshin_little_proximal_joint" multiplier="1.0"/>
  </joint>
  <transmission name="qbshin_transmission">
    <type>transmission_interface/qbMoveTransmission</type>
    <joint name="qbshin_little_proximal_virtual_joint">
      <hardwareInterface>hardware_interface/EffortJointInterface</hardwareInterface>
    </joint>
    <actuator name="qbshin_little_proximal_virtual_joint">
      <hardwareInterface>hardware_interface/EffortJointInterface</hardwareInterface>
    </actuator>
  </transmission>
  <gazebo reference="qbshin_little_proximal_virtual_joint">
    <!-- TODO: add other Gazebo Joint properties (http://sdformat.org/spec?elem=joint) -->
  </gazebo>
  <link name="qbshin_little_proximal_link">
    <inertial>
      <mass value="0.0082"/>
      <origin rpy="0 0 0" xyz="8.7707437e-03 -1.7863138e-03 0.0"/>
      <inertia ixx="2.2722068e-07" ixy="1.1586053e-08" ixz="0.0" iyy="5.5947233e-07" iyz="0.0" izz="5.9562195e-07"/>
    </inertial>
    <visual>
      <origin rpy="0 0 0" xyz="0 0 0"/>
      <geometry>
        <mesh filename="package://meshes/mc_h_pad_25_urdf.stl" scale="0.001 0.001 0.001"/>
      </geometry>
      <material name="qbshin/proximal"/>
    </visual>
    <collision>
      <origin rpy="0 0 0" xyz="0 0 0"/>
      <geometry>
        <mesh filename="package://meshes/mc_h_pad_25_urdf.stl" scale="0.001 0.001 0.001"/>
      </geometry>
    </collision>
  </link>
  <gazebo reference="qbshin_little_proximal_link">
    <self_collide>1</self_collide>
    <!-- TODO: add other Gazebo Link properties (http://sdformat.org/spec?elem=link) -->
    <!--      <collision>-->
    <!--        <surface>-->
    <!--          <contact>-->
    <!--            <ode>-->
    <!--              <kp>1.0</kp>-->
    <!--              <kd>0.01</kd>-->
    <!--              <max_vel>0.0</max_vel>-->
    <!--              <min_depth>0.001</min_depth>-->
    <!--            </ode>-->
    <!--          </contact>-->
    <!--          <friction>-->
    <!--            <ode>-->
    <!--              <mu>0.9</mu>-->
    <!--              <mu2>0.9</mu2>-->
    <!--            </ode>-->
    <!--          </friction>-->
    <!--        </surface>-->
    <!--      </collision>-->
  </gazebo>
  <joint name="qbshin_little_middle_joint" type="revolute">
    <origin rpy="0.0 0.0 0.0" xyz="0.01 0 0"/>
    <parent link="qbshin_little_proximal_link"/>
    <child link="qbshin_little_middle_virtual_link"/>
    <axis xyz="0 0 -1"/>
    <dynamics damping="0.0" friction="0.0"/>
    <limit effort="100" lower="0.0" upper="0.785" velocity="100"/>
    <mimic joint="qbshin_synergy_joint" multiplier="0.785"/>
  </joint>
  <transmission name="qbshin_transmission">
    <type>transmission_interface/qbMoveTransmission</type>
    <joint name="qbshin_little_middle_joint">
      <hardwareInterface>hardware_interface/EffortJointInterface</hardwareInterface>
    </joint>
    <actuator name="qbshin_little_middle_joint">
      <hardwareInterface>hardware_interface/EffortJointInterface</hardwareInterface>
    </actuator>
  </transmission>
  <gazebo reference="qbshin_little_middle_joint">
    <!-- TODO: add other Gazebo Joint properties (http://sdformat.org/spec?elem=joint) -->
  </gazebo>
  <link name="qbshin_little_middle_virtual_link">
    <inertial>
      <origin rpy="0 0 0" xyz="0 0 0"/>
      <mass value="1e-4"/>
      <inertia ixx="1e-9" ixy="0.0" ixz="0.0" iyy="1e-9" iyz="0.0" izz="1e-9"/>
    </inertial>
  </link>
  <joint name="qbshin_little_middle_virtual_joint" type="revolute">
    <origin rpy="0 0 0" xyz="0.013 0 0"/>
    <parent link="qbshin_little_middle_virtual_link"/>
    <child link="qbshin_little_middle_link"/>
    <axis xyz="0 0 -1"/>
    <dynamics damping="0.0" friction="0.0"/>
    <limit effort="100" lower="0.0" upper="0.785" velocity="100"/>
    <mimic joint="qbshin_little_middle_joint" multiplier="1.0"/>
  </joint>
  <transmission name="qbshin_transmission">
    <type>transmission_interface/qbMoveTransmission</type>
    <joint name="qbshin_little_middle_virtual_joint">
      <hardwareInterface>hardware_interface/EffortJointInterface</hardwareInterface>
    </joint>
    <actuator name="qbshin_little_middle_virtual_joint">
      <hardwareInterface>hardware_interface/EffortJointInterface</hardwareInterface>
    </actuator>
  </transmission>
  <gazebo reference="qbshin_little_middle_virtual_joint">
    <!-- TODO: add other Gazebo Joint properties (http://sdformat.org/spec?elem=joint) -->
  </gazebo>
  <link name="qbshin_little_middle_link">
    <inertial>
      <mass value="0.0082"/>
      <origin rpy="0 0 0" xyz="8.7707437e-03 -1.7863138e-03 0.0"/>
      <inertia ixx="2.2722068e-07" ixy="1.1586053e-08" ixz="0.0" iyy="5.5947233e-07" iyz="0.0" izz="5.9562195e-07"/>
    </inertial>
    <visual>
      <origin rpy="0 0 0" xyz="0 0 0"/>
      <geometry>
        <mesh filename="package://meshes/mc_h_pad_21_urdf.stl" scale="0.001 0.001 0.001"/>
      </geometry>
      <material name="qbshin/middle"/>
    </visual>
    <collision>
      <origin rpy="0 0 0" xyz="0 0 0"/>
      <geometry>
        <mesh filename="package://meshes/mc_h_pad_21_urdf.stl" scale="0.001 0.001 0.001"/>
      </geometry>
    </collision>
  </link>
  <gazebo reference="qbshin_little_middle_link">
    <self_collide>1</self_collide>
    <!-- TODO: add other Gazebo Link properties (http://sdformat.org/spec?elem=link) -->
    <!--      <collision>-->
    <!--        <surface>-->
    <!--          <contact>-->
    <!--            <ode>-->
    <!--              <kp>1.0</kp>-->
    <!--              <kd>0.01</kd>-->
    <!--              <max_vel>0.0</max_vel>-->
    <!--              <min_depth>0.001</min_depth>-->
    <!--            </ode>-->
    <!--          </contact>-->
    <!--          <friction>-->
    <!--            <ode>-->
    <!--              <mu>0.9</mu>-->
    <!--              <mu2>0.9</mu2>-->
    <!--            </ode>-->
    <!--          </friction>-->
    <!--        </surface>-->
    <!--      </collision>-->
  </gazebo>
  <joint name="qbshin_little_distal_joint" type="revolute">
    <origin rpy="0.0 0.0 0.0" xyz="0.008 0.002 0"/>
    <parent link="qbshin_little_middle_link"/>
    <child link="qbshin_little_distal_virtual_link"/>
    <axis xyz="0 0 -1"/>
    <dynamics damping="0.0" friction="0.0"/>
    <limit effort="100" lower="0.0" upper="0.785" velocity="100"/>
    <mimic joint="qbshin_synergy_joint" multiplier="0.785"/>
  </joint>
  <transmission name="qbshin_transmission">
    <type>transmission_interface/qbMoveTransmission</type>
    <joint name="qbshin_little_distal_joint">
      <hardwareInterface>hardware_interface/EffortJointInterface</hardwareInterface>
    </joint>
    <actuator name="qbshin_little_distal_joint">
      <hardwareInterface>hardware_interface/EffortJointInterface</hardwareInterface>
    </actuator>
  </transmission>
  <gazebo reference="qbshin_little_distal_joint">
    <!-- TODO: add other Gazebo Joint properties (http://sdformat.org/spec?elem=joint) -->
  </gazebo>
  <link name="qbshin_little_distal_virtual_link">
    <inertial>
      <origin rpy="0 0 0" xyz="0 0 0"/>
      <mass value="1e-4"/>
      <inertia ixx="1e-9" ixy="0.0" ixz="0.0" iyy="1e-9" iyz="0.0" izz="1e-9"/>
    </inertial>
  </link>
  <joint name="qbshin_little_distal_virtual_joint" type="revolute">
    <origin rpy="0 0 0" xyz="0.013 0 0"/>
    <parent link="qbshin_little_distal_virtual_link"/>
    <child link="qbshin_little_distal_link"/>
    <axis xyz="0 0 -1"/>
    <dynamics damping="0.0" friction="0.0"/>
    <limit effort="100" lower="0.0" upper="0.785" velocity="100"/>
    <mimic joint="qbshin_little_distal_joint" multiplier="1.0"/>
  </joint>
  <transmission name="qbshin_transmission">
    <type>transmission_interface/qbMoveTransmission</type>
    <joint name="qbshin_little_distal_virtual_joint">
      <hardwareInterface>hardware_interface/EffortJointInterface</hardwareInterface>
    </joint>
    <actuator name="qbshin_little_distal_virtual_joint">
      <hardwareInterface>hardware_interface/EffortJointInterface</hardwareInterface>
    </actuator>
  </transmission>
  <gazebo reference="qbshin_little_distal_virtual_joint">
    <!-- TODO: add other Gazebo Joint properties (http://sdformat.org/spec?elem=joint) -->
  </gazebo>
  <link name="qbshin_little_distal_link">
    <inertial>
      <mass value="0.009"/>
      <origin rpy="0 0 0" xyz="8.8025467e-03 -1.7219289e-03 0.0"/>
      <inertia ixx="2.6586142e-07" ixy="1.2416847e-08" ixz="0.0" iyy="5.9935767e-07" iyz="0.0" izz="6.6781963e-07"/>
    </inertial>
    <visual>
      <origin rpy="0 0 0" xyz="0 0 0"/>
      <geometry>
        <mesh filename="package://meshes/mc_h_pad_dist_urdf.stl" scale="0.001 0.001 0.001"/>
      </geometry>
      <material name="qbshin/distal"/>
    </visual>
    <collision>
      <origin rpy="0 0 0" xyz="0 0 0"/>
      <geometry>
        <mesh filename="package://meshes/mc_h_pad_dist_urdf.stl" scale="0.001 0.001 0.001"/>
      </geometry>
    </collision>
  </link>
  <gazebo reference="qbshin_little_distal_link">
    <self_collide>1</self_collide>
    <!-- TODO: add other Gazebo Link properties (http://sdformat.org/spec?elem=link) -->
    <!--      <collision>-->
    <!--        <surface>-->
    <!--          <contact>-->
    <!--            <ode>-->
    <!--              <kp>1.0</kp>-->
    <!--              <kd>0.01</kd>-->
    <!--              <max_vel>0.0</max_vel>-->
    <!--              <min_depth>0.001</min_depth>-->
    <!--            </ode>-->
    <!--          </contact>-->
    <!--          <friction>-->
    <!--            <ode>-->
    <!--              <mu>0.9</mu>-->
    <!--              <mu2>0.9</mu2>-->
    <!--            </ode>-->
    <!--          </friction>-->
    <!--        </surface>-->
    <!--      </collision>-->
  </gazebo>
  <joint name="qbshin_end_effector_fixed_joint" type="fixed">
    <origin rpy="-1.57 0 0" xyz="-0.03 0.082 -0.09"/>
    <parent link="qbshin_palm_link"/>
    <child link="qbshin_end_effector_link"/>
  </joint>
  <link name="qbshin_end_effector_link"/>
</robot>
