<?xml version="1.0"?>
<robot xmlns:xacro="http://wiki.ros.org/xacro" name="$(arg robot_model)_robot">
  <!--
    This is a top-level xacro instantiating the Gazebo-specific version of the
    'ur_robot' macro (ie: 'ur_robot_gazebo') and passing it values for all its
    required arguments.

    This file should be considered the Gazebo-specific variant of the file
    with the same name in the ur_description package. It accepts the same
    arguments, but instead of configuring everything for a real robot, will
    generate a Gazebo-compatible URDF with a ros_control hardware_interface
    attached to it.

    Only use this top-level xacro if you plan on spawning the robot in Gazebo
    'by itself', without any gripper or any other geometry attached.

    If you need to attach an end-effector, camera or need to integrate the
    robot into a larger workcell and want to spawn that as a single entity in
    Gazebo, DO NOT EDIT THIS FILE.

    Instead: create a new top-level xacro, give it a proper name, include the
    required '.xacro' files, instantiate the models (ie: call the macros) and
    connect everything by adding the appropriate joints.
  -->

  <!--
    Import main macro.

    NOTE: this imports the Gazebo-wrapper main macro, NOT the regular
          xacro macro (which is hosted by ur_description).
  -->
  <xacro:include filename="$(find agri_gazebo_scene)/urdf/ur_macro.xacro" />
    <gazebo>
      <plugin name="ros_control" filename="libgazebo_ros_control.so">
        <!--robotNamespace>/</robotNamespace-->
        <!--robotSimType>gazebo_ros_control/DefaultRobotHWSim</robotSimType-->
      </plugin>
    </gazebo>

  <!--Declare arguments -->
  <xacro:arg name="joint_limit_params" default=""/>
  <xacro:arg name="physical_params" default=""/>
  <xacro:arg name="kinematics_params" default=""/>
  <xacro:arg name="visual_params" default=""/>
  <xacro:arg name="prefix1" default=""/>
  <xacro:arg name="prefix2" default=""/>
  <!--
    legal values:
      - hardware_interface/PositionJointInterface
      - hardware_interface/VelocityJointInterface
      - hardware_interface/EffortJointInterface

    NOTE: this value must correspond to the controller configured in the
          controller .yaml files in the 'config' directory.
  -->
  <xacro:arg name="transmission_hw_interface" default="hardware_interface/EffortJointInterface"/>
  <xacro:arg name="safety_limits" default="false"/>
  <xacro:arg name="safety_pos_margin" default="0.15"/>
  <xacro:arg name="safety_k_position" default="20"/>

  <!-- Instantiate the Gazebo robot and pass it all the required arguments. -->
  <xacro:ur_robot_gazebo
    prefix="$(arg prefix1)"
    joint_limits_parameters_file="$(arg joint_limit_params)"
    kinematics_parameters_file="$(arg kinematics_params)"
    physical_parameters_file="$(arg physical_params)"
    visual_parameters_file="$(arg visual_params)"
    transmission_hw_interface="$(arg transmission_hw_interface)"
    safety_limits="$(arg safety_limits)"
    safety_pos_margin="$(arg safety_pos_margin)"
    safety_k_position="$(arg safety_k_position)"
  />

  <xacro:ur_robot_gazebo
    prefix="$(arg prefix2)"
    joint_limits_parameters_file="$(arg joint_limit_params)"
    kinematics_parameters_file="$(arg kinematics_params)"
    physical_parameters_file="$(arg physical_params)"
    visual_parameters_file="$(arg visual_params)"
    transmission_hw_interface="$(arg transmission_hw_interface)"
    safety_limits="$(arg safety_limits)"
    safety_pos_margin="$(arg safety_pos_margin)"
    safety_k_position="$(arg safety_k_position)"
  />

  <!--
    Attach the Gazebo model to Gazebo's world frame.

    Note: if you're looking to integrate a UR into a larger scene and need
    to add EEFs or other parts, DO NOT change this file or the 'world' link
    here. Create a NEW xacro instead and decide whether you need to add
    a 'world' link there.
  -->
  <link name="world"/>
  <joint name="world_joint" type="prismatic">
    <parent link="world"/>
    <child link="$(arg prefix1)base_link"/>
    <origin xyz="0 0 2" rpy="0 0 0"/>
    <axis xyz="0 1 0" />
    <limit lower="-10" upper="10"
        effort="10" velocity="10"/>
  </joint>

  <transmission name="world_trans">
      <type>transmission_interface/SimpleTransmission</type>
      <joint name="world_joint">
        <hardwareInterface>$(arg transmission_hw_interface)</hardwareInterface>
      </joint>
      <actuator name="$world_joint_motor">
        <mechanicalReduction>1</mechanicalReduction>
      </actuator>
    </transmission>

  <joint name="connect_joint" type="fixed">
    <parent link="$(arg prefix1)base_link"/>
    <child link="$(arg prefix2)base_link"/>
    <origin xyz="0 -1 0" rpy="0 0 0"/>
  </joint>

  <link name="tool0_controller"/>
  <joint name="tool_controller_fake_joint" type="fixed">
    <parent link="$(arg prefix1)tool0"/>
    <child link="tool0_controller"/>
    <origin xyz="0 0 0" rpy="0 0 0"/>
  </joint>

  <link name="qbsh_left">
    <visual>
     <origin xyz="0 0 0" rpy="0 0 0" />
     <geometry>
        <mesh filename="package://agri_gazebo_scene/meshes/qbsh_left.stl"/>
     </geometry>
   </visual>
   <collision>
     <origin xyz="0 0 0" rpy="0 0 0" />
     <geometry>
        <mesh filename="package://agri_gazebo_scene/meshes/qbsh_left.stl"/>
     </geometry>
   </collision>
  </link>

  <link name="qbsh_right">
    <visual>
     <origin xyz="0 0 0" rpy="0 0 0" />
     <geometry>
        <mesh filename="package://agri_gazebo_scene/meshes/qbsh_left.stl"/>
     </geometry>
   </visual>
   <collision>
     <origin xyz="0 0 0" rpy="0 0 0" />
     <geometry>
        <mesh filename="package://agri_gazebo_scene/meshes/qbsh_left.stl" />
     </geometry>
   </collision>
  </link>

  <joint name="qbsh_left_joint" type="fixed">
    <parent link="$(arg prefix1)tool0"/>
    <child link="qbsh_left"/>
    <origin xyz="0 0 0" rpy="0 0 3.14"/>
  </joint>

  <joint name="qbsh_right_joint" type="fixed">
    <parent link="$(arg prefix2)tool0"/>
    <child link="qbsh_right"/>
    <origin xyz="0 0 0" rpy="0 0 3.14"/>
  </joint>
  
   <joint name="$(arg prefix1)camera_joint" type="fixed">
    <axis xyz="0 1 0" />
    <origin xyz="0.1 0 0" rpy="0 0 0"/>
    <parent link="$(arg prefix1)base_link"/>
    <child link="$(arg prefix1)camera_link"/>
  </joint>

  <!-- Camera -->
  <link name="$(arg prefix1)camera_link">
    <visual>
      <origin xyz="0 0 0" rpy="0 0 0"/>
      <geometry>
    <box size="0.05 0.05 0.05"/>
      </geometry>
      <material name="grey"/>
    </visual>
  </link>

    <gazebo reference="$(arg prefix1)camera_link">
    <sensor type="camera" name="camera1">
      <update_rate>30.0</update_rate>
      <camera name="head">
        <horizontal_fov>1.3962634</horizontal_fov>
        <image>
          <width>800</width>
          <height>800</height>
          <format>R8G8B8</format>
        </image>
        <clip>
          <near>0.02</near>
          <far>300</far>
        </clip>
        <noise>
          <type>gaussian</type>
          <!-- Noise is sampled independently per pixel on each frame.
               That pixel's noise value is added to each of its color
               channels, which at that point lie in the range [0,1]. -->
          <mean>0.0</mean>
          <stddev>0.007</stddev>
        </noise>
      </camera>
      <plugin name="camera_controller" filename="libgazebo_ros_camera.so">
        <alwaysOn>true</alwaysOn>
        <updateRate>0.0</updateRate>
        <cameraName>$(arg prefix1)/camera1</cameraName>
        <imageTopicName>image_raw</imageTopicName>
        <cameraInfoTopicName>camera_info</cameraInfoTopicName>
        <frameName>$(arg prefix1)camera_link</frameName>
        <hackBaseline>0.07</hackBaseline>
        <distortionK1>0.0</distortionK1>
        <distortionK2>0.0</distortionK2>
        <distortionK3>0.0</distortionK3>
        <distortionT1>0.0</distortionT1>
        <distortionT2>0.0</distortionT2>
      </plugin>
    </sensor>
  </gazebo>

    
   <joint name="$(arg prefix2)camera_joint" type="fixed">
    <axis xyz="0 1 0" />
    <origin xyz="0.1 0 0" rpy="0 0 0"/>
    <parent link="$(arg prefix2)base_link"/>
    <child link="$(arg prefix2)camera_link"/>
  </joint>

  <!-- Camera -->
  <link name="$(arg prefix2)camera_link">
    <visual>
      <origin xyz="0 0 0" rpy="0 0 0"/>
      <geometry>
    <box size="0.05 0.05 0.05"/>
      </geometry>
      <material name="grey"/>
    </visual>
  </link>

    <gazebo reference="$(arg prefix2)camera_link">
    <sensor type="camera" name="camera1">
      <update_rate>30.0</update_rate>
      <camera name="head">
        <horizontal_fov>1.3962634</horizontal_fov>
        <image>
          <width>800</width>
          <height>800</height>
          <format>R8G8B8</format>
        </image>
        <clip>
          <near>0.02</near>
          <far>300</far>
        </clip>
        <noise>
          <type>gaussian</type>
          <!-- Noise is sampled independently per pixel on each frame.
               That pixel's noise value is added to each of its color
               channels, which at that point lie in the range [0,1]. -->
          <mean>0.0</mean>
          <stddev>0.007</stddev>
        </noise>
      </camera>
      <plugin name="camera_controller" filename="libgazebo_ros_camera.so">
        <alwaysOn>true</alwaysOn>
        <updateRate>0.0</updateRate>
        <cameraName>$(arg prefix2)/camera1</cameraName>
        <imageTopicName>image_raw</imageTopicName>
        <cameraInfoTopicName>camera_info</cameraInfoTopicName>
        <frameName>$(arg prefix2)camera_link</frameName>
        <hackBaseline>0.07</hackBaseline>
        <distortionK1>0.0</distortionK1>
        <distortionK2>0.0</distortionK2>
        <distortionK3>0.0</distortionK3>
        <distortionT1>0.0</distortionT1>
        <distortionT2>0.0</distortionT2>
      </plugin>
    </sensor>
  </gazebo>

</robot>
